2018-12-12 15:03:41,776 ERROR: Exception on /favicon.ico [GET] [in c:\users\balint\pycharmprojects\microblog\venv\lib\site-packages\flask\app.py:1761]
Traceback (most recent call last):
  File "c:\users\balint\pycharmprojects\microblog\venv\lib\site-packages\flask\app.py", line 2292, in wsgi_app
    response = self.full_dispatch_request()
  File "c:\users\balint\pycharmprojects\microblog\venv\lib\site-packages\flask\app.py", line 1815, in full_dispatch_request
    rv = self.handle_user_exception(e)
  File "c:\users\balint\pycharmprojects\microblog\venv\lib\site-packages\flask\app.py", line 1718, in handle_user_exception
    reraise(exc_type, exc_value, tb)
  File "c:\users\balint\pycharmprojects\microblog\venv\lib\site-packages\flask\_compat.py", line 35, in reraise
    raise value
  File "c:\users\balint\pycharmprojects\microblog\venv\lib\site-packages\flask\app.py", line 1811, in full_dispatch_request
    rv = self.preprocess_request()
  File "c:\users\balint\pycharmprojects\microblog\venv\lib\site-packages\flask\app.py", line 2087, in preprocess_request
    rv = func()
  File "C:\Users\Balint\PycharmProjects\microblog\app\main\routes.py", line 17, in before_request
    db.session.commit()
  File "c:\users\balint\pycharmprojects\microblog\venv\lib\site-packages\sqlalchemy\orm\scoping.py", line 153, in do
    return getattr(self.registry(), name)(*args, **kwargs)
  File "c:\users\balint\pycharmprojects\microblog\venv\lib\site-packages\sqlalchemy\orm\session.py", line 954, in commit
    self.transaction.commit()
  File "c:\users\balint\pycharmprojects\microblog\venv\lib\site-packages\sqlalchemy\orm\session.py", line 474, in commit
    self.session.dispatch.after_commit(self.session)
  File "c:\users\balint\pycharmprojects\microblog\venv\lib\site-packages\sqlalchemy\event\attr.py", line 246, in __call__
    fn(*args, **kw)
  File "C:\Users\Balint\PycharmProjects\microblog\app\models.py", line 34, in after_commit
    for obj in session._changes['add']:
TypeError: 'NoneType' object is not subscriptable
2018-12-12 16:00:17,848 INFO: Microblog startup [in C:\Users\Balint\PycharmProjects\microblog\app\__init__.py:77]
2018-12-12 16:00:19,815 ERROR: Exception on / [GET] [in c:\users\balint\pycharmprojects\microblog\venv\lib\site-packages\flask\app.py:1761]
Traceback (most recent call last):
  File "c:\users\balint\pycharmprojects\microblog\venv\lib\site-packages\flask\app.py", line 2292, in wsgi_app
    response = self.full_dispatch_request()
  File "c:\users\balint\pycharmprojects\microblog\venv\lib\site-packages\flask\app.py", line 1815, in full_dispatch_request
    rv = self.handle_user_exception(e)
  File "c:\users\balint\pycharmprojects\microblog\venv\lib\site-packages\flask\app.py", line 1718, in handle_user_exception
    reraise(exc_type, exc_value, tb)
  File "c:\users\balint\pycharmprojects\microblog\venv\lib\site-packages\flask\_compat.py", line 35, in reraise
    raise value
  File "c:\users\balint\pycharmprojects\microblog\venv\lib\site-packages\flask\app.py", line 1811, in full_dispatch_request
    rv = self.preprocess_request()
  File "c:\users\balint\pycharmprojects\microblog\venv\lib\site-packages\flask\app.py", line 2087, in preprocess_request
    rv = func()
  File "C:\Users\Balint\PycharmProjects\microblog\app\main\routes.py", line 18, in before_request
    db.session.commit()
  File "c:\users\balint\pycharmprojects\microblog\venv\lib\site-packages\sqlalchemy\orm\scoping.py", line 153, in do
    return getattr(self.registry(), name)(*args, **kwargs)
  File "c:\users\balint\pycharmprojects\microblog\venv\lib\site-packages\sqlalchemy\orm\session.py", line 954, in commit
    self.transaction.commit()
  File "c:\users\balint\pycharmprojects\microblog\venv\lib\site-packages\sqlalchemy\orm\session.py", line 474, in commit
    self.session.dispatch.after_commit(self.session)
  File "c:\users\balint\pycharmprojects\microblog\venv\lib\site-packages\sqlalchemy\event\attr.py", line 246, in __call__
    fn(*args, **kw)
  File "C:\Users\Balint\PycharmProjects\microblog\app\models.py", line 34, in after_commit
    for obj in session._changes['add']:
TypeError: 'NoneType' object is not subscriptable
2018-12-12 16:00:21,275 ERROR: Exception on /favicon.ico [GET] [in c:\users\balint\pycharmprojects\microblog\venv\lib\site-packages\flask\app.py:1761]
Traceback (most recent call last):
  File "c:\users\balint\pycharmprojects\microblog\venv\lib\site-packages\flask\app.py", line 2292, in wsgi_app
    response = self.full_dispatch_request()
  File "c:\users\balint\pycharmprojects\microblog\venv\lib\site-packages\flask\app.py", line 1815, in full_dispatch_request
    rv = self.handle_user_exception(e)
  File "c:\users\balint\pycharmprojects\microblog\venv\lib\site-packages\flask\app.py", line 1718, in handle_user_exception
    reraise(exc_type, exc_value, tb)
  File "c:\users\balint\pycharmprojects\microblog\venv\lib\site-packages\flask\_compat.py", line 35, in reraise
    raise value
  File "c:\users\balint\pycharmprojects\microblog\venv\lib\site-packages\flask\app.py", line 1811, in full_dispatch_request
    rv = self.preprocess_request()
  File "c:\users\balint\pycharmprojects\microblog\venv\lib\site-packages\flask\app.py", line 2087, in preprocess_request
    rv = func()
  File "C:\Users\Balint\PycharmProjects\microblog\app\main\routes.py", line 18, in before_request
    db.session.commit()
  File "c:\users\balint\pycharmprojects\microblog\venv\lib\site-packages\sqlalchemy\orm\scoping.py", line 153, in do
    return getattr(self.registry(), name)(*args, **kwargs)
  File "c:\users\balint\pycharmprojects\microblog\venv\lib\site-packages\sqlalchemy\orm\session.py", line 954, in commit
    self.transaction.commit()
  File "c:\users\balint\pycharmprojects\microblog\venv\lib\site-packages\sqlalchemy\orm\session.py", line 474, in commit
    self.session.dispatch.after_commit(self.session)
  File "c:\users\balint\pycharmprojects\microblog\venv\lib\site-packages\sqlalchemy\event\attr.py", line 246, in __call__
    fn(*args, **kw)
  File "C:\Users\Balint\PycharmProjects\microblog\app\models.py", line 34, in after_commit
    for obj in session._changes['add']:
TypeError: 'NoneType' object is not subscriptable
2018-12-12 16:00:52,676 INFO: Microblog startup [in C:\Users\Balint\PycharmProjects\microblog\app\__init__.py:77]
2018-12-12 16:09:29,613 INFO: Microblog startup [in C:\Users\Balint\PycharmProjects\microblog\app\__init__.py:77]
2018-12-12 16:09:35,074 INFO: Microblog startup [in C:\Users\Balint\PycharmProjects\microblog\app\__init__.py:77]
2018-12-12 22:38:28,320 INFO: Microblog startup [in C:\Users\Balint\PycharmProjects\microblog\app\__init__.py:81]
2018-12-12 22:38:37,915 INFO: Microblog startup [in C:\Users\Balint\PycharmProjects\microblog\app\__init__.py:81]
2018-12-12 22:38:44,707 INFO: Microblog startup [in C:\Users\Balint\PycharmProjects\microblog\app\__init__.py:81]
2018-12-12 22:39:06,552 INFO: Microblog startup [in C:\Users\Balint\PycharmProjects\microblog\app\__init__.py:81]
2018-12-12 22:39:11,592 INFO: Microblog startup [in C:\Users\Balint\PycharmProjects\microblog\app\__init__.py:81]
2018-12-12 22:39:14,833 INFO: Microblog startup [in C:\Users\Balint\PycharmProjects\microblog\app\__init__.py:81]
