2018-12-11 20:19:07,867 INFO: Microblog startup [in C:\Users\Balint\PycharmProjects\microblog\app\__init__.py:77]
2018-12-11 20:40:12,936 INFO: Microblog startup [in C:\Users\Balint\PycharmProjects\microblog\app\__init__.py:77]
2018-12-11 20:40:22,127 INFO: Microblog startup [in C:\Users\Balint\PycharmProjects\microblog\app\__init__.py:77]
2018-12-11 21:16:55,988 INFO: Microblog startup [in C:\Users\Balint\PycharmProjects\microblog\app\__init__.py:77]
2018-12-11 21:23:28,431 INFO: Microblog startup [in C:\Users\Balint\PycharmProjects\microblog\app\__init__.py:77]
2018-12-11 21:23:34,521 INFO: Microblog startup [in C:\Users\Balint\PycharmProjects\microblog\app\__init__.py:77]
2018-12-11 21:41:34,045 INFO: Microblog startup [in C:\Users\Balint\PycharmProjects\microblog\app\__init__.py:77]
2018-12-11 21:41:35,246 ERROR: Exception on / [GET] [in c:\users\balint\pycharmprojects\microblog\venv\lib\site-packages\flask\app.py:1761]
Traceback (most recent call last):
  File "c:\users\balint\pycharmprojects\microblog\venv\lib\site-packages\flask\app.py", line 2292, in wsgi_app
    response = self.full_dispatch_request()
  File "c:\users\balint\pycharmprojects\microblog\venv\lib\site-packages\flask\app.py", line 1815, in full_dispatch_request
    rv = self.handle_user_exception(e)
  File "c:\users\balint\pycharmprojects\microblog\venv\lib\site-packages\flask\app.py", line 1718, in handle_user_exception
    reraise(exc_type, exc_value, tb)
  File "c:\users\balint\pycharmprojects\microblog\venv\lib\site-packages\flask\_compat.py", line 35, in reraise
    raise value
  File "c:\users\balint\pycharmprojects\microblog\venv\lib\site-packages\flask\app.py", line 1811, in full_dispatch_request
    rv = self.preprocess_request()
  File "c:\users\balint\pycharmprojects\microblog\venv\lib\site-packages\flask\app.py", line 2087, in preprocess_request
    rv = func()
  File "C:\Users\Balint\PycharmProjects\microblog\app\main\routes.py", line 15, in before_request
    if current_user.is_authenticated:
  File "c:\users\balint\pycharmprojects\microblog\venv\lib\site-packages\werkzeug\local.py", line 347, in __getattr__
    return getattr(self._get_current_object(), name)
  File "c:\users\balint\pycharmprojects\microblog\venv\lib\site-packages\werkzeug\local.py", line 306, in _get_current_object
    return self.__local()
  File "c:\users\balint\pycharmprojects\microblog\venv\lib\site-packages\flask_login\utils.py", line 26, in <lambda>
    current_user = LocalProxy(lambda: _get_user())
  File "c:\users\balint\pycharmprojects\microblog\venv\lib\site-packages\flask_login\utils.py", line 335, in _get_user
    current_app.login_manager._load_user()
  File "c:\users\balint\pycharmprojects\microblog\venv\lib\site-packages\flask_login\login_manager.py", line 359, in _load_user
    return self.reload_user()
  File "c:\users\balint\pycharmprojects\microblog\venv\lib\site-packages\flask_login\login_manager.py", line 321, in reload_user
    user = self.user_callback(user_id)
  File "C:\Users\Balint\PycharmProjects\microblog\app\models.py", line 134, in load_user
    return User.query.get(int(id))
  File "c:\users\balint\pycharmprojects\microblog\venv\lib\site-packages\flask_sqlalchemy\__init__.py", line 512, in __get__
    mapper = orm.class_mapper(type)
  File "c:\users\balint\pycharmprojects\microblog\venv\lib\site-packages\sqlalchemy\orm\base.py", line 421, in class_mapper
    mapper = _inspect_mapped_class(class_, configure=configure)
  File "c:\users\balint\pycharmprojects\microblog\venv\lib\site-packages\sqlalchemy\orm\base.py", line 400, in _inspect_mapped_class
    mapper._configure_all()
  File "c:\users\balint\pycharmprojects\microblog\venv\lib\site-packages\sqlalchemy\orm\mapper.py", line 1276, in _configure_all
    configure_mappers()
  File "c:\users\balint\pycharmprojects\microblog\venv\lib\site-packages\sqlalchemy\orm\mapper.py", line 3033, in configure_mappers
    mapper._post_configure_properties()
  File "c:\users\balint\pycharmprojects\microblog\venv\lib\site-packages\sqlalchemy\orm\mapper.py", line 1832, in _post_configure_properties
    prop.init()
  File "c:\users\balint\pycharmprojects\microblog\venv\lib\site-packages\sqlalchemy\orm\interfaces.py", line 183, in init
    self.do_init()
  File "c:\users\balint\pycharmprojects\microblog\venv\lib\site-packages\sqlalchemy\orm\relationships.py", line 1655, in do_init
    self._process_dependent_arguments()
  File "c:\users\balint\pycharmprojects\microblog\venv\lib\site-packages\sqlalchemy\orm\relationships.py", line 1680, in _process_dependent_arguments
    setattr(self, attr, attr_value())
  File "c:\users\balint\pycharmprojects\microblog\venv\lib\site-packages\sqlalchemy\ext\declarative\clsregistry.py", line 281, in __call__
    x = eval(self.arg, globals(), self._dict)
  File "<string>", line 1, in <module>
  File "c:\users\balint\pycharmprojects\microblog\venv\lib\site-packages\sqlalchemy\ext\declarative\clsregistry.py", line 213, in __getattr__
    % (self.cls, key))
sqlalchemy.exc.InvalidRequestError: Class <class 'app.models.Message'> does not have a mapped column named 'recipient'
2018-12-11 21:41:37,328 ERROR: Exception on /favicon.ico [GET] [in c:\users\balint\pycharmprojects\microblog\venv\lib\site-packages\flask\app.py:1761]
Traceback (most recent call last):
  File "c:\users\balint\pycharmprojects\microblog\venv\lib\site-packages\flask\app.py", line 2292, in wsgi_app
    response = self.full_dispatch_request()
  File "c:\users\balint\pycharmprojects\microblog\venv\lib\site-packages\flask\app.py", line 1815, in full_dispatch_request
    rv = self.handle_user_exception(e)
  File "c:\users\balint\pycharmprojects\microblog\venv\lib\site-packages\flask\app.py", line 1718, in handle_user_exception
    reraise(exc_type, exc_value, tb)
  File "c:\users\balint\pycharmprojects\microblog\venv\lib\site-packages\flask\_compat.py", line 35, in reraise
    raise value
  File "c:\users\balint\pycharmprojects\microblog\venv\lib\site-packages\flask\app.py", line 1811, in full_dispatch_request
    rv = self.preprocess_request()
  File "c:\users\balint\pycharmprojects\microblog\venv\lib\site-packages\flask\app.py", line 2087, in preprocess_request
    rv = func()
  File "C:\Users\Balint\PycharmProjects\microblog\app\main\routes.py", line 15, in before_request
    if current_user.is_authenticated:
  File "c:\users\balint\pycharmprojects\microblog\venv\lib\site-packages\werkzeug\local.py", line 347, in __getattr__
    return getattr(self._get_current_object(), name)
  File "c:\users\balint\pycharmprojects\microblog\venv\lib\site-packages\werkzeug\local.py", line 306, in _get_current_object
    return self.__local()
  File "c:\users\balint\pycharmprojects\microblog\venv\lib\site-packages\flask_login\utils.py", line 26, in <lambda>
    current_user = LocalProxy(lambda: _get_user())
  File "c:\users\balint\pycharmprojects\microblog\venv\lib\site-packages\flask_login\utils.py", line 335, in _get_user
    current_app.login_manager._load_user()
  File "c:\users\balint\pycharmprojects\microblog\venv\lib\site-packages\flask_login\login_manager.py", line 359, in _load_user
    return self.reload_user()
  File "c:\users\balint\pycharmprojects\microblog\venv\lib\site-packages\flask_login\login_manager.py", line 321, in reload_user
    user = self.user_callback(user_id)
  File "C:\Users\Balint\PycharmProjects\microblog\app\models.py", line 134, in load_user
    return User.query.get(int(id))
  File "c:\users\balint\pycharmprojects\microblog\venv\lib\site-packages\flask_sqlalchemy\__init__.py", line 512, in __get__
    mapper = orm.class_mapper(type)
  File "c:\users\balint\pycharmprojects\microblog\venv\lib\site-packages\sqlalchemy\orm\base.py", line 421, in class_mapper
    mapper = _inspect_mapped_class(class_, configure=configure)
  File "c:\users\balint\pycharmprojects\microblog\venv\lib\site-packages\sqlalchemy\orm\base.py", line 400, in _inspect_mapped_class
    mapper._configure_all()
  File "c:\users\balint\pycharmprojects\microblog\venv\lib\site-packages\sqlalchemy\orm\mapper.py", line 1276, in _configure_all
    configure_mappers()
  File "c:\users\balint\pycharmprojects\microblog\venv\lib\site-packages\sqlalchemy\orm\mapper.py", line 3030, in configure_mappers
    raise e
sqlalchemy.exc.InvalidRequestError: One or more mappers failed to initialize - can't proceed with initialization of other mappers. Triggering mapper: 'Mapper|User|user'. Original exception was: Class <class 'app.models.Message'> does not have a mapped column named 'recipient'
2018-12-11 21:41:47,128 INFO: Microblog startup [in C:\Users\Balint\PycharmProjects\microblog\app\__init__.py:77]
2018-12-11 21:41:52,790 INFO: Microblog startup [in C:\Users\Balint\PycharmProjects\microblog\app\__init__.py:77]
2018-12-11 21:42:00,132 INFO: Microblog startup [in C:\Users\Balint\PycharmProjects\microblog\app\__init__.py:77]
