2018-12-11 08:19:25,480 ERROR: Exception on /login [POST] [in c:\users\balint\pycharmprojects\microblog\venv\lib\site-packages\flask\app.py:1761]
Traceback (most recent call last):
  File "c:\users\balint\pycharmprojects\microblog\venv\lib\site-packages\sqlalchemy\engine\base.py", line 2158, in _wrap_pool_connect
    return fn()
  File "c:\users\balint\pycharmprojects\microblog\venv\lib\site-packages\sqlalchemy\pool.py", line 400, in connect
    return _ConnectionFairy._checkout(self)
  File "c:\users\balint\pycharmprojects\microblog\venv\lib\site-packages\sqlalchemy\pool.py", line 788, in _checkout
    fairy = _ConnectionRecord.checkout(pool)
  File "c:\users\balint\pycharmprojects\microblog\venv\lib\site-packages\sqlalchemy\pool.py", line 529, in checkout
    rec = pool._do_get()
  File "c:\users\balint\pycharmprojects\microblog\venv\lib\site-packages\sqlalchemy\pool.py", line 1193, in _do_get
    self._dec_overflow()
  File "c:\users\balint\pycharmprojects\microblog\venv\lib\site-packages\sqlalchemy\util\langhelpers.py", line 66, in __exit__
    compat.reraise(exc_type, exc_value, exc_tb)
  File "c:\users\balint\pycharmprojects\microblog\venv\lib\site-packages\sqlalchemy\util\compat.py", line 249, in reraise
    raise value
  File "c:\users\balint\pycharmprojects\microblog\venv\lib\site-packages\sqlalchemy\pool.py", line 1190, in _do_get
    return self._create_connection()
  File "c:\users\balint\pycharmprojects\microblog\venv\lib\site-packages\sqlalchemy\pool.py", line 347, in _create_connection
    return _ConnectionRecord(self)
  File "c:\users\balint\pycharmprojects\microblog\venv\lib\site-packages\sqlalchemy\pool.py", line 474, in __init__
    self.__connect(first_connect_check=True)
  File "c:\users\balint\pycharmprojects\microblog\venv\lib\site-packages\sqlalchemy\pool.py", line 671, in __connect
    connection = pool._invoke_creator(self)
  File "c:\users\balint\pycharmprojects\microblog\venv\lib\site-packages\sqlalchemy\engine\strategies.py", line 106, in connect
    return dialect.connect(*cargs, **cparams)
  File "c:\users\balint\pycharmprojects\microblog\venv\lib\site-packages\sqlalchemy\engine\default.py", line 412, in connect
    return self.dbapi.connect(*cargs, **cparams)
  File "c:\users\balint\pycharmprojects\microblog\venv\lib\site-packages\psycopg2\__init__.py", line 130, in connect
    conn = _connect(dsn, connection_factory=connection_factory, **kwasync)
psycopg2.OperationalError: could not connect to server: Connection timed out (0x0000274C/10060)
	Is the server running on host "192.168.1.193" and accepting
	TCP/IP connections on port 5432?


The above exception was the direct cause of the following exception:

Traceback (most recent call last):
  File "c:\users\balint\pycharmprojects\microblog\venv\lib\site-packages\flask\app.py", line 2292, in wsgi_app
    response = self.full_dispatch_request()
  File "c:\users\balint\pycharmprojects\microblog\venv\lib\site-packages\flask\app.py", line 1815, in full_dispatch_request
    rv = self.handle_user_exception(e)
  File "c:\users\balint\pycharmprojects\microblog\venv\lib\site-packages\flask\app.py", line 1718, in handle_user_exception
    reraise(exc_type, exc_value, tb)
  File "c:\users\balint\pycharmprojects\microblog\venv\lib\site-packages\flask\_compat.py", line 35, in reraise
    raise value
  File "c:\users\balint\pycharmprojects\microblog\venv\lib\site-packages\flask\app.py", line 1813, in full_dispatch_request
    rv = self.dispatch_request()
  File "c:\users\balint\pycharmprojects\microblog\venv\lib\site-packages\flask\app.py", line 1799, in dispatch_request
    return self.view_functions[rule.endpoint](**req.view_args)
  File "C:\Users\Balint\PycharmProjects\microblog\app\routes.py", line 69, in login
    user = User.query.filter_by(username=form.username.data).first()
  File "c:\users\balint\pycharmprojects\microblog\venv\lib\site-packages\sqlalchemy\orm\query.py", line 2895, in first
    ret = list(self[0:1])
  File "c:\users\balint\pycharmprojects\microblog\venv\lib\site-packages\sqlalchemy\orm\query.py", line 2687, in __getitem__
    return list(res)
  File "c:\users\balint\pycharmprojects\microblog\venv\lib\site-packages\sqlalchemy\orm\query.py", line 2995, in __iter__
    return self._execute_and_instances(context)
  File "c:\users\balint\pycharmprojects\microblog\venv\lib\site-packages\sqlalchemy\orm\query.py", line 3016, in _execute_and_instances
    close_with_result=True)
  File "c:\users\balint\pycharmprojects\microblog\venv\lib\site-packages\sqlalchemy\orm\query.py", line 3025, in _get_bind_args
    **kw
  File "c:\users\balint\pycharmprojects\microblog\venv\lib\site-packages\sqlalchemy\orm\query.py", line 3007, in _connection_from_session
    conn = self.session.connection(**kw)
  File "c:\users\balint\pycharmprojects\microblog\venv\lib\site-packages\sqlalchemy\orm\session.py", line 1046, in connection
    execution_options=execution_options)
  File "c:\users\balint\pycharmprojects\microblog\venv\lib\site-packages\sqlalchemy\orm\session.py", line 1051, in _connection_for_bind
    engine, execution_options)
  File "c:\users\balint\pycharmprojects\microblog\venv\lib\site-packages\sqlalchemy\orm\session.py", line 409, in _connection_for_bind
    conn = bind.contextual_connect()
  File "c:\users\balint\pycharmprojects\microblog\venv\lib\site-packages\sqlalchemy\engine\base.py", line 2123, in contextual_connect
    self._wrap_pool_connect(self.pool.connect, None),
  File "c:\users\balint\pycharmprojects\microblog\venv\lib\site-packages\sqlalchemy\engine\base.py", line 2162, in _wrap_pool_connect
    e, dialect, self)
  File "c:\users\balint\pycharmprojects\microblog\venv\lib\site-packages\sqlalchemy\engine\base.py", line 1476, in _handle_dbapi_exception_noconnection
    exc_info
  File "c:\users\balint\pycharmprojects\microblog\venv\lib\site-packages\sqlalchemy\util\compat.py", line 265, in raise_from_cause
    reraise(type(exception), exception, tb=exc_tb, cause=cause)
  File "c:\users\balint\pycharmprojects\microblog\venv\lib\site-packages\sqlalchemy\util\compat.py", line 248, in reraise
    raise value.with_traceback(tb)
  File "c:\users\balint\pycharmprojects\microblog\venv\lib\site-packages\sqlalchemy\engine\base.py", line 2158, in _wrap_pool_connect
    return fn()
  File "c:\users\balint\pycharmprojects\microblog\venv\lib\site-packages\sqlalchemy\pool.py", line 400, in connect
    return _ConnectionFairy._checkout(self)
  File "c:\users\balint\pycharmprojects\microblog\venv\lib\site-packages\sqlalchemy\pool.py", line 788, in _checkout
    fairy = _ConnectionRecord.checkout(pool)
  File "c:\users\balint\pycharmprojects\microblog\venv\lib\site-packages\sqlalchemy\pool.py", line 529, in checkout
    rec = pool._do_get()
  File "c:\users\balint\pycharmprojects\microblog\venv\lib\site-packages\sqlalchemy\pool.py", line 1193, in _do_get
    self._dec_overflow()
  File "c:\users\balint\pycharmprojects\microblog\venv\lib\site-packages\sqlalchemy\util\langhelpers.py", line 66, in __exit__
    compat.reraise(exc_type, exc_value, exc_tb)
  File "c:\users\balint\pycharmprojects\microblog\venv\lib\site-packages\sqlalchemy\util\compat.py", line 249, in reraise
    raise value
  File "c:\users\balint\pycharmprojects\microblog\venv\lib\site-packages\sqlalchemy\pool.py", line 1190, in _do_get
    return self._create_connection()
  File "c:\users\balint\pycharmprojects\microblog\venv\lib\site-packages\sqlalchemy\pool.py", line 347, in _create_connection
    return _ConnectionRecord(self)
  File "c:\users\balint\pycharmprojects\microblog\venv\lib\site-packages\sqlalchemy\pool.py", line 474, in __init__
    self.__connect(first_connect_check=True)
  File "c:\users\balint\pycharmprojects\microblog\venv\lib\site-packages\sqlalchemy\pool.py", line 671, in __connect
    connection = pool._invoke_creator(self)
  File "c:\users\balint\pycharmprojects\microblog\venv\lib\site-packages\sqlalchemy\engine\strategies.py", line 106, in connect
    return dialect.connect(*cargs, **cparams)
  File "c:\users\balint\pycharmprojects\microblog\venv\lib\site-packages\sqlalchemy\engine\default.py", line 412, in connect
    return self.dbapi.connect(*cargs, **cparams)
  File "c:\users\balint\pycharmprojects\microblog\venv\lib\site-packages\psycopg2\__init__.py", line 130, in connect
    conn = _connect(dsn, connection_factory=connection_factory, **kwasync)
sqlalchemy.exc.OperationalError: (psycopg2.OperationalError) could not connect to server: Connection timed out (0x0000274C/10060)
	Is the server running on host "192.168.1.193" and accepting
	TCP/IP connections on port 5432?
 (Background on this error at: http://sqlalche.me/e/e3q8)
2018-12-11 08:22:35,556 INFO: Microblog startup [in C:\Users\Balint\PycharmProjects\microblog\app\__init__.py:58]
